2020-06-09 21:03:34,603 -  nornir.core -  WARNING -        run() - Task 'remote_command' has not been run – 0 hosts selected
2020-06-09 21:03:42,796 -  nornir.core -  WARNING -        run() - Task 'remote_command' has not been run – 0 hosts selected
2020-06-09 21:05:41,697 -  nornir.core -  WARNING -        run() - Task 'remote_command' has not been run – 0 hosts selected
2020-06-09 21:05:47,714 -  nornir.core -  WARNING -        run() - Task 'remote_command' has not been run – 0 hosts selected
2020-06-09 21:06:03,856 -  nornir.core -  WARNING -        run() - Task 'remote_command' has not been run – 0 hosts selected
2020-06-09 21:11:26,705 -  nornir.core -  WARNING -        run() - Task 'netmiko_send_command' has not been run – 0 hosts selected
2020-06-09 21:25:35,871 -  nornir.core -  WARNING -        run() - Task 'get_temp' has not been run – 0 hosts selected
2020-06-09 21:25:52,915 -  nornir.core -  WARNING -        run() - Task 'get_temp' has not been run – 0 hosts selected
2020-06-09 21:26:20,910 -  nornir.core -  WARNING -        run() - Task 'get_temp' has not been run – 0 hosts selected
2020-06-09 21:27:39,784 -  nornir.core -  WARNING -        run() - Task 'get_temp' has not been run – 0 hosts selected
2020-06-09 21:28:37,777 -  nornir.core -  WARNING -        run() - Task 'get_temp' has not been run – 0 hosts selected
2020-06-09 21:29:08,845 -  nornir.core -  WARNING -        run() - Task 'get_temp' has not been run – 0 hosts selected
2020-06-09 21:29:54,383 -  nornir.core -     INFO -        run() - Running task 'hi' with args {} on 2 hosts
2020-06-09 21:29:54,383 - nornir.core.task -    ERROR -      start() - Host 'monpi.lan': task 'hi' failed with traceback:
Traceback (most recent call last):
  File "/home/jack/.local/lib/python3.6/site-packages/nornir/core/task.py", line 85, in start
    r = self.task(self, **self.params)
  File "sshmon.py", line 23, in hi
    print(f"hi! My name is {task.host.name} and I live in {task.host['site']}")
  File "/home/jack/.local/lib/python3.6/site-packages/nornir/core/inventory.py", line 150, in __getitem__
    return self.data[item]
KeyError: 'site'

2020-06-09 21:29:54,383 - nornir.core.task -    ERROR -      start() - Host 'netpi.lan': task 'hi' failed with traceback:
Traceback (most recent call last):
  File "/home/jack/.local/lib/python3.6/site-packages/nornir/core/task.py", line 85, in start
    r = self.task(self, **self.params)
  File "sshmon.py", line 23, in hi
    print(f"hi! My name is {task.host.name} and I live in {task.host['site']}")
  File "/home/jack/.local/lib/python3.6/site-packages/nornir/core/inventory.py", line 150, in __getitem__
    return self.data[item]
KeyError: 'site'

2020-06-09 21:29:54,383 -  nornir.core -  WARNING -        run() - Task 'get_temp' has not been run – 0 hosts selected
2020-06-09 21:30:11,419 -  nornir.core -     INFO -        run() - Running task 'hi' with args {} on 2 hosts
2020-06-09 21:30:11,419 - nornir.core.task -    ERROR -      start() - Host 'monpi.lan': task 'hi' failed with traceback:
Traceback (most recent call last):
  File "/home/jack/.local/lib/python3.6/site-packages/nornir/core/task.py", line 85, in start
    r = self.task(self, **self.params)
  File "sshmon.py", line 23, in hi
    print(f"hi! My name is {task.host.name} and I live in {task.host['groups']}")
  File "/home/jack/.local/lib/python3.6/site-packages/nornir/core/inventory.py", line 150, in __getitem__
    return self.data[item]
KeyError: 'groups'

2020-06-09 21:30:11,420 - nornir.core.task -    ERROR -      start() - Host 'netpi.lan': task 'hi' failed with traceback:
Traceback (most recent call last):
  File "/home/jack/.local/lib/python3.6/site-packages/nornir/core/task.py", line 85, in start
    r = self.task(self, **self.params)
  File "sshmon.py", line 23, in hi
    print(f"hi! My name is {task.host.name} and I live in {task.host['groups']}")
  File "/home/jack/.local/lib/python3.6/site-packages/nornir/core/inventory.py", line 150, in __getitem__
    return self.data[item]
KeyError: 'groups'

2020-06-09 21:30:11,420 -  nornir.core -  WARNING -        run() - Task 'get_temp' has not been run – 0 hosts selected
2020-06-09 21:31:15,747 -  nornir.core -     INFO -        run() - Running task 'hi' with args {} on 2 hosts
2020-06-09 21:31:15,748 - nornir.core.task -    ERROR -      start() - Host 'monpi.lan': task 'hi' failed with traceback:
Traceback (most recent call last):
  File "/home/jack/.local/lib/python3.6/site-packages/nornir/core/task.py", line 85, in start
    r = self.task(self, **self.params)
  File "sshmon.py", line 14, in hi
    print(f"hi! My name is {task.host.name} and I live in {task.host['groups']}")
  File "/home/jack/.local/lib/python3.6/site-packages/nornir/core/inventory.py", line 150, in __getitem__
    return self.data[item]
KeyError: 'groups'

2020-06-09 21:31:15,748 - nornir.core.task -    ERROR -      start() - Host 'netpi.lan': task 'hi' failed with traceback:
Traceback (most recent call last):
  File "/home/jack/.local/lib/python3.6/site-packages/nornir/core/task.py", line 85, in start
    r = self.task(self, **self.params)
  File "sshmon.py", line 14, in hi
    print(f"hi! My name is {task.host.name} and I live in {task.host['groups']}")
  File "/home/jack/.local/lib/python3.6/site-packages/nornir/core/inventory.py", line 150, in __getitem__
    return self.data[item]
KeyError: 'groups'

2020-06-09 21:32:53,691 -  nornir.core -     INFO -        run() - Running task 'hi' with args {} on 2 hosts
2020-06-09 21:32:53,691 - nornir.core.task -    ERROR -      start() - Host 'monpi.lan': task 'hi' failed with traceback:
Traceback (most recent call last):
  File "/home/jack/.local/lib/python3.6/site-packages/nornir/core/task.py", line 85, in start
    r = self.task(self, **self.params)
  File "sshmon.py", line 14, in hi
    print(f"hi! My name is {task.host.name} and I live in {task.host['groups']}")
  File "/home/jack/.local/lib/python3.6/site-packages/nornir/core/inventory.py", line 150, in __getitem__
    return self.data[item]
KeyError: 'groups'

2020-06-09 21:32:53,691 - nornir.core.task -    ERROR -      start() - Host 'netpi.lan': task 'hi' failed with traceback:
Traceback (most recent call last):
  File "/home/jack/.local/lib/python3.6/site-packages/nornir/core/task.py", line 85, in start
    r = self.task(self, **self.params)
  File "sshmon.py", line 14, in hi
    print(f"hi! My name is {task.host.name} and I live in {task.host['groups']}")
  File "/home/jack/.local/lib/python3.6/site-packages/nornir/core/inventory.py", line 150, in __getitem__
    return self.data[item]
KeyError: 'groups'

2020-06-09 21:35:49,037 -  nornir.core -     INFO -        run() - Running task 'hi' with args {} on 2 hosts
2020-06-09 21:35:49,037 - nornir.core.task -    ERROR -      start() - Host 'monpi.lan': task 'hi' failed with traceback:
Traceback (most recent call last):
  File "/home/jack/.local/lib/python3.6/site-packages/nornir/core/task.py", line 85, in start
    r = self.task(self, **self.params)
  File "sshmon.py", line 10, in hi
    print(f"hi! My name is {task.host.name} and I live in {task.host['groups']}")
  File "/home/jack/.local/lib/python3.6/site-packages/nornir/core/inventory.py", line 150, in __getitem__
    return self.data[item]
KeyError: 'groups'

2020-06-09 21:35:49,037 - nornir.core.task -    ERROR -      start() - Host 'netpi.lan': task 'hi' failed with traceback:
Traceback (most recent call last):
  File "/home/jack/.local/lib/python3.6/site-packages/nornir/core/task.py", line 85, in start
    r = self.task(self, **self.params)
  File "sshmon.py", line 10, in hi
    print(f"hi! My name is {task.host.name} and I live in {task.host['groups']}")
  File "/home/jack/.local/lib/python3.6/site-packages/nornir/core/inventory.py", line 150, in __getitem__
    return self.data[item]
KeyError: 'groups'

2020-06-09 21:36:26,451 -  nornir.core -     INFO -        run() - Running task 'hi' with args {} on 2 hosts
2020-06-09 21:36:26,451 - nornir.core.task -    ERROR -      start() - Host 'monpi.lan': task 'hi' failed with traceback:
Traceback (most recent call last):
  File "/home/jack/.local/lib/python3.6/site-packages/nornir/core/task.py", line 85, in start
    r = self.task(self, **self.params)
  File "sshmon.py", line 10, in hi
    print(f"hi! My name is {task.host.name} and I live in {task.host['groups']}")
  File "/home/jack/.local/lib/python3.6/site-packages/nornir/core/inventory.py", line 150, in __getitem__
    return self.data[item]
KeyError: 'groups'

2020-06-09 21:36:26,451 - nornir.core.task -    ERROR -      start() - Host 'netpi.lan': task 'hi' failed with traceback:
Traceback (most recent call last):
  File "/home/jack/.local/lib/python3.6/site-packages/nornir/core/task.py", line 85, in start
    r = self.task(self, **self.params)
  File "sshmon.py", line 10, in hi
    print(f"hi! My name is {task.host.name} and I live in {task.host['groups']}")
  File "/home/jack/.local/lib/python3.6/site-packages/nornir/core/inventory.py", line 150, in __getitem__
    return self.data[item]
KeyError: 'groups'

2020-06-09 21:36:40,732 -  nornir.core -     INFO -        run() - Running task 'hi' with args {} on 2 hosts
2020-06-09 21:36:40,733 - nornir.core.task -    ERROR -      start() - Host 'monpi.lan': task 'hi' failed with traceback:
Traceback (most recent call last):
  File "/home/jack/.local/lib/python3.6/site-packages/nornir/core/task.py", line 85, in start
    r = self.task(self, **self.params)
  File "sshmon.py", line 10, in hi
    print(f"hi! My name is {task.host.name} and I live in {task.host['group']}")
  File "/home/jack/.local/lib/python3.6/site-packages/nornir/core/inventory.py", line 150, in __getitem__
    return self.data[item]
KeyError: 'group'

2020-06-09 21:36:40,733 - nornir.core.task -    ERROR -      start() - Host 'netpi.lan': task 'hi' failed with traceback:
Traceback (most recent call last):
  File "/home/jack/.local/lib/python3.6/site-packages/nornir/core/task.py", line 85, in start
    r = self.task(self, **self.params)
  File "sshmon.py", line 10, in hi
    print(f"hi! My name is {task.host.name} and I live in {task.host['group']}")
  File "/home/jack/.local/lib/python3.6/site-packages/nornir/core/inventory.py", line 150, in __getitem__
    return self.data[item]
KeyError: 'group'

2020-06-09 21:37:03,930 -  nornir.core -     INFO -        run() - Running task 'hi' with args {} on 2 hosts
2020-06-09 21:37:03,931 - nornir.core.task -    ERROR -      start() - Host 'monpi.lan': task 'hi' failed with traceback:
Traceback (most recent call last):
  File "/home/jack/.local/lib/python3.6/site-packages/nornir/core/task.py", line 85, in start
    r = self.task(self, **self.params)
  File "sshmon.py", line 10, in hi
    print(f"hi! My name is {task.host.name} and I live in {task.host['username']}")
  File "/home/jack/.local/lib/python3.6/site-packages/nornir/core/inventory.py", line 150, in __getitem__
    return self.data[item]
KeyError: 'username'

2020-06-09 21:37:03,931 - nornir.core.task -    ERROR -      start() - Host 'netpi.lan': task 'hi' failed with traceback:
Traceback (most recent call last):
  File "/home/jack/.local/lib/python3.6/site-packages/nornir/core/task.py", line 85, in start
    r = self.task(self, **self.params)
  File "sshmon.py", line 10, in hi
    print(f"hi! My name is {task.host.name} and I live in {task.host['username']}")
  File "/home/jack/.local/lib/python3.6/site-packages/nornir/core/inventory.py", line 150, in __getitem__
    return self.data[item]
KeyError: 'username'

2020-06-09 21:38:18,088 -  nornir.core -     INFO -        run() - Running task 'hi' with args {} on 2 hosts
2020-06-09 21:38:18,089 - nornir.core.task -    ERROR -      start() - Host 'monpi.lan': task 'hi' failed with traceback:
Traceback (most recent call last):
  File "/home/jack/.local/lib/python3.6/site-packages/nornir/core/task.py", line 85, in start
    r = self.task(self, **self.params)
  File "sshmon.py", line 11, in hi
    print(f"hi! My name is {task.host.name} and I live in {task.host['username']}")
  File "/home/jack/.local/lib/python3.6/site-packages/nornir/core/inventory.py", line 150, in __getitem__
    return self.data[item]
KeyError: 'username'

2020-06-09 21:38:18,089 - nornir.core.task -    ERROR -      start() - Host 'netpi.lan': task 'hi' failed with traceback:
Traceback (most recent call last):
  File "/home/jack/.local/lib/python3.6/site-packages/nornir/core/task.py", line 85, in start
    r = self.task(self, **self.params)
  File "sshmon.py", line 11, in hi
    print(f"hi! My name is {task.host.name} and I live in {task.host['username']}")
  File "/home/jack/.local/lib/python3.6/site-packages/nornir/core/inventory.py", line 150, in __getitem__
    return self.data[item]
KeyError: 'username'

2020-06-09 21:38:59,869 -  nornir.core -     INFO -        run() - Running task 'hi' with args {} on 2 hosts
2020-06-09 21:38:59,870 - nornir.core.task -    ERROR -      start() - Host 'monpi.lan': task 'hi' failed with traceback:
Traceback (most recent call last):
  File "/home/jack/.local/lib/python3.6/site-packages/nornir/core/task.py", line 85, in start
    r = self.task(self, **self.params)
  File "sshmon.py", line 11, in hi
    print(f"hi! My name is {task.host.name} and I live in {task.host['username']}")
  File "/home/jack/.local/lib/python3.6/site-packages/nornir/core/inventory.py", line 150, in __getitem__
    return self.data[item]
KeyError: 'username'

2020-06-09 21:38:59,870 - nornir.core.task -    ERROR -      start() - Host 'netpi.lan': task 'hi' failed with traceback:
Traceback (most recent call last):
  File "/home/jack/.local/lib/python3.6/site-packages/nornir/core/task.py", line 85, in start
    r = self.task(self, **self.params)
  File "sshmon.py", line 11, in hi
    print(f"hi! My name is {task.host.name} and I live in {task.host['username']}")
  File "/home/jack/.local/lib/python3.6/site-packages/nornir/core/inventory.py", line 150, in __getitem__
    return self.data[item]
KeyError: 'username'

2020-06-09 21:39:23,388 -  nornir.core -     INFO -        run() - Running task 'hi' with args {} on 2 hosts
2020-06-09 21:39:39,018 -  nornir.core -     INFO -        run() - Running task 'hi' with args {} on 2 hosts
2020-06-09 21:40:56,216 -  nornir.core -     INFO -        run() - Running task 'hi' with args {} on 2 hosts
2020-06-09 21:41:14,302 -  nornir.core -     INFO -        run() - Running task 'get_temp' with args {} on 2 hosts
2020-06-09 21:41:46,117 -  nornir.core -     INFO -        run() - Running task 'get_temp' with args {} on 2 hosts
2020-06-09 21:42:28,348 -  nornir.core -     INFO -        run() - Running task 'get_temp' with args {} on 2 hosts
2020-06-09 21:43:24,509 -  nornir.core -     INFO -        run() - Running task 'get_temp' with args {} on 2 hosts
2020-06-10 10:12:55,369 -  nornir.core -     INFO -        run() - Running task 'get_temp' with args {} on 2 hosts
2020-06-10 10:13:05,572 - nornir.core.task -    ERROR -      start() - Host 'monpi.lan': task 'get_temp' failed with traceback:
Traceback (most recent call last):
  File "/home/jack/.local/lib/python3.6/site-packages/nornir/core/task.py", line 85, in start
    r = self.task(self, **self.params)
  File "/home/jack/code/homelab_collector/sshmon.py", line 14, in get_temp
    result["pwd"] = shell.run(["pwd"])
NameError: name 'result' is not defined

2020-06-10 10:15:11,334 -  nornir.core -     INFO -        run() - Running task 'get_temp' with args {} on 2 hosts
2020-06-10 10:15:48,243 -  nornir.core -     INFO -        run() - Running task 'get_temp' with args {} on 2 hosts
2020-06-10 10:16:03,088 -  nornir.core -     INFO -        run() - Running task 'get_temp' with args {} on 2 hosts
2020-06-10 10:16:20,283 -  nornir.core -     INFO -        run() - Running task 'get_temp' with args {} on 2 hosts
2020-06-10 10:34:13,001 -  nornir.core -     INFO -        run() - Running task 'get_temp' with args {} on 2 hosts
2020-06-10 10:35:01,407 -  nornir.core -     INFO -        run() - Running task 'get_temp' with args {} on 2 hosts
2020-06-10 10:35:44,498 -  nornir.core -     INFO -        run() - Running task 'get_temp' with args {} on 2 hosts
2020-06-10 10:36:23,135 -  nornir.core -     INFO -        run() - Running task 'get_temp' with args {} on 2 hosts
2020-06-10 10:36:51,167 -  nornir.core -     INFO -        run() - Running task 'get_temp' with args {} on 2 hosts
2020-06-10 10:37:04,613 -  nornir.core -     INFO -        run() - Running task 'get_temp' with args {} on 2 hosts
2020-06-10 10:37:19,502 -  nornir.core -     INFO -        run() - Running task 'get_temp' with args {} on 2 hosts
2020-06-10 10:37:31,819 -  nornir.core -     INFO -        run() - Running task 'get_temp' with args {} on 2 hosts
2020-06-10 10:41:40,658 -  nornir.core -     INFO -        run() - Running task 'get_data_pi' with args {} on 2 hosts
2020-06-10 10:45:25,256 -  nornir.core -     INFO -        run() - Running task 'get_data_pi' with args {} on 2 hosts
2020-06-10 10:46:31,519 -  nornir.core -     INFO -        run() - Running task 'get_data_pi' with args {} on 2 hosts
2020-06-10 10:54:12,772 -  nornir.core -     INFO -        run() - Running task 'get_data_pi' with args {} on 2 hosts
2020-06-10 10:57:11,344 -  nornir.core -     INFO -        run() - Running task 'get_data_pi' with args {} on 2 hosts
2020-06-10 10:57:35,745 -  nornir.core -     INFO -        run() - Running task 'get_data_pi' with args {} on 2 hosts
2020-06-10 10:57:54,995 - nornir.core.task -    ERROR -      start() - Host 'monpi.lan': task 'get_data_pi' failed with traceback:
Traceback (most recent call last):
  File "/home/jack/.local/lib/python3.6/site-packages/nornir/core/task.py", line 85, in start
    r = self.task(self, **self.params)
  File "/home/jack/code/homelab_collector/sshmon.py", line 17, in get_data_pi
    result["temp"] = shell.run(["vcgencmd", "measure_temp"]).output.decode("utf-8").strip().replace("temp=","")[:-2]
AttributeError: 'str' object has no attribute 'readlines'

2020-06-10 10:58:30,843 -  nornir.core -     INFO -        run() - Running task 'get_data_pi' with args {} on 2 hosts
2020-06-10 10:59:07,441 -  nornir.core -     INFO -        run() - Running task 'get_data_pi' with args {} on 2 hosts
2020-06-10 10:59:22,093 -  nornir.core -     INFO -        run() - Running task 'get_data_pi' with args {} on 2 hosts
2020-06-10 10:59:46,177 -  nornir.core -     INFO -        run() - Running task 'get_data_pi' with args {} on 2 hosts
2020-06-10 11:02:26,983 -  nornir.core -     INFO -        run() - Running task 'get_data_pi' with args {} on 2 hosts
2020-06-10 11:02:57,928 -  nornir.core -     INFO -        run() - Running task 'get_data_pi' with args {} on 2 hosts
2020-06-10 11:03:20,644 -  nornir.core -     INFO -        run() - Running task 'get_data_pi' with args {} on 2 hosts
2020-06-10 11:03:34,613 -  nornir.core -     INFO -        run() - Running task 'get_data_pi' with args {} on 2 hosts
2020-06-10 11:05:05,764 -  nornir.core -     INFO -        run() - Running task 'get_data_pi' with args {} on 2 hosts
2020-06-10 11:05:25,955 - nornir.core.task -    ERROR -      start() - Host 'monpi.lan': task 'get_data_pi' failed with traceback:
Traceback (most recent call last):
  File "/home/jack/.local/lib/python3.6/site-packages/nornir/core/task.py", line 85, in start
    r = self.task(self, **self.params)
  File "/home/jack/code/homelab_collector/sshmon.py", line 18, in get_data_pi
    result["mem"] = shell.run(["free","-t", "-m"]).output.decode("utf-8").join("test")
TypeError: join() takes exactly one argument (0 given)

2020-06-10 11:18:07,606 -  nornir.core -     INFO -        run() - Running task 'get_data_pi' with args {} on 2 hosts
2020-06-10 11:21:41,877 -  nornir.core -     INFO -        run() - Running task 'get_data_pi' with args {} on 2 hosts
2020-06-10 11:22:35,275 - nornir.core.task -    ERROR -      start() - Host 'monpi.lan': task 'get_data_pi' failed with traceback:
Traceback (most recent call last):
  File "/home/jack/.local/lib/python3.6/site-packages/nornir/core/task.py", line 85, in start
    r = self.task(self, **self.params)
  File "/home/jack/code/homelab_collector/sshmon.py", line 19, in get_data_pi
    result["mem"] = shell.run(["sh", "-c","vmstat"]).output.decode("utf-8")
  File "/home/jack/.local/lib/python3.6/site-packages/spur/ssh.py", line 169, in run
    return self.spawn(*args, **kwargs).wait_for_result()
  File "/home/jack/.local/lib/python3.6/site-packages/spur/ssh.py", line 209, in spawn
    raise NoSuchCommandError(command[0])
spur.errors.NoSuchCommandError: Command not found: wmstat. Check that wmstat is installed and on $PATH

2020-06-10 11:23:10,932 - nornir.core.task -    ERROR -      start() - Host 'netpi.lan': task 'get_data_pi' failed with traceback:
Traceback (most recent call last):
  File "/home/jack/.local/lib/python3.6/site-packages/nornir/core/task.py", line 85, in start
    r = self.task(self, **self.params)
  File "/home/jack/code/homelab_collector/sshmon.py", line 19, in get_data_pi
    shell.run(["sh", "-c", "echo $PATH"])
  File "/home/jack/.local/lib/python3.6/site-packages/spur/ssh.py", line 169, in run
    return self.spawn(*args, **kwargs).wait_for_result()
  File "/home/jack/.local/lib/python3.6/site-packages/spur/ssh.py", line 209, in spawn
    raise NoSuchCommandError(command[0])
spur.errors.NoSuchCommandError: Command not found: wmstat. Check that wmstat is installed and on $PATH

2020-06-10 11:23:19,489 -  nornir.core -     INFO -        run() - Running task 'get_data_pi' with args {} on 2 hosts
2020-06-10 11:23:46,421 -  nornir.core -     INFO -        run() - Running task 'get_data_pi' with args {} on 2 hosts
2020-06-10 11:23:59,658 -  nornir.core -     INFO -        run() - Running task 'get_data_pi' with args {} on 2 hosts
2020-06-10 11:25:35,119 -  nornir.core -     INFO -        run() - Running task 'get_data_pi' with args {} on 2 hosts
2020-06-10 11:29:41,161 -  nornir.core -     INFO -        run() - Running task 'get_data_pi' with args {} on 2 hosts
2020-06-10 11:30:45,246 -  nornir.core -     INFO -        run() - Running task 'get_data_pi' with args {} on 2 hosts
2020-06-10 11:32:16,550 -  nornir.core -     INFO -        run() - Running task 'get_data_pi' with args {} on 2 hosts
2020-06-10 11:33:15,424 -  nornir.core -     INFO -        run() - Running task 'get_data_pi' with args {} on 2 hosts
2020-06-10 11:33:36,715 -  nornir.core -     INFO -        run() - Running task 'get_data_pi' with args {} on 2 hosts
2020-06-10 11:43:21,191 -  nornir.core -     INFO -        run() - Running task 'get_data_pi' with args {} on 2 hosts
2020-06-10 11:44:10,850 -  nornir.core -     INFO -        run() - Running task 'get_data_pi' with args {} on 2 hosts
2020-06-10 11:44:29,308 -  nornir.core -     INFO -        run() - Running task 'get_data_pi' with args {} on 2 hosts
2020-06-10 11:50:40,933 -  nornir.core -     INFO -        run() - Running task 'get_data_pi' with args {} on 2 hosts
2020-06-10 11:52:31,347 -  nornir.core -     INFO -        run() - Running task 'get_data_pi' with args {} on 2 hosts
2020-06-10 11:53:49,838 -  nornir.core -     INFO -        run() - Running task 'get_data_pi' with args {} on 2 hosts
2020-06-10 11:59:06,417 -  nornir.core -     INFO -        run() - Running task 'get_data_pi' with args {} on 2 hosts
2020-06-10 12:01:21,703 -  nornir.core -     INFO -        run() - Running task 'get_data_pi' with args {} on 2 hosts
2020-06-10 12:02:07,200 -  nornir.core -     INFO -        run() - Running task 'get_data_pi' with args {} on 2 hosts
2020-06-10 12:02:32,784 -  nornir.core -     INFO -        run() - Running task 'get_data_pi' with args {} on 2 hosts
2020-06-10 12:08:53,734 -  nornir.core -     INFO -        run() - Running task 'get_data_pi' with args {} on 2 hosts
2020-06-10 12:09:42,905 -  nornir.core -     INFO -        run() - Running task 'get_data_pi' with args {} on 2 hosts
2020-06-10 12:10:34,654 -  nornir.core -     INFO -        run() - Running task 'get_data_pi' with args {} on 2 hosts
2020-06-10 12:11:04,995 -  nornir.core -     INFO -        run() - Running task 'get_data_pi' with args {} on 2 hosts
2020-06-10 12:11:46,942 -  nornir.core -     INFO -        run() - Running task 'get_data_pi' with args {} on 2 hosts
2020-06-10 12:46:48,934 -  nornir.core -     INFO -        run() - Running task 'get_data_pi' with args {} on 2 hosts
2020-06-10 12:47:11,902 -  nornir.core -     INFO -        run() - Running task 'get_data_pi' with args {} on 2 hosts
2020-06-10 12:47:29,793 -  nornir.core -     INFO -        run() - Running task 'get_data_pi' with args {} on 2 hosts
2020-06-10 12:47:55,133 -  nornir.core -     INFO -        run() - Running task 'get_data_pi' with args {} on 2 hosts
2020-06-10 12:48:02,607 -  nornir.core -     INFO -        run() - Running task 'get_data_pi' with args {} on 2 hosts
2020-06-10 12:48:19,136 -  nornir.core -     INFO -        run() - Running task 'get_data_pi' with args {} on 2 hosts
2020-06-10 12:48:53,280 -  nornir.core -     INFO -        run() - Running task 'get_data_pi' with args {} on 2 hosts
2020-06-10 12:49:10,413 -  nornir.core -     INFO -        run() - Running task 'get_data_pi' with args {} on 2 hosts
2020-06-10 12:49:18,733 -  nornir.core -     INFO -        run() - Running task 'get_data_pi' with args {} on 2 hosts
2020-06-10 12:49:31,238 -  nornir.core -     INFO -        run() - Running task 'get_data_pi' with args {} on 2 hosts
2020-06-10 12:49:53,505 -  nornir.core -     INFO -        run() - Running task 'get_data_pi' with args {} on 2 hosts
2020-06-10 12:50:01,389 -  nornir.core -     INFO -        run() - Running task 'get_data_pi' with args {} on 2 hosts
2020-06-10 12:50:04,350 -  nornir.core -     INFO -        run() - Running task 'get_data_pi' with args {} on 2 hosts
2020-06-10 15:00:50,021 -  nornir.core -     INFO -        run() - Running task 'get_data_pi' with args {} on 2 hosts
2020-06-10 15:01:30,309 -  nornir.core -     INFO -        run() - Running task 'get_data_pi' with args {} on 2 hosts
2020-06-10 15:03:09,483 -  nornir.core -     INFO -        run() - Running task 'get_data_pi' with args {} on 2 hosts
2020-06-10 15:04:46,756 -  nornir.core -     INFO -        run() - Running task 'get_data_pi' with args {} on 2 hosts
2020-06-10 15:06:47,907 -  nornir.core -     INFO -        run() - Running task 'get_data_pi' with args {} on 2 hosts
